Workbook
Name PostePosition: PostePosition!$B$20:$C$42

Sheet BD-TABsAintégrer
A1: MFB Sport | B1: - | C1: -
A23: DataSource | B23: ID_footballer | C23: Gender | D23: FirstName | E23: LastName | F23: Position | G23: CountryOfOrigin | H23: YearOfBirth | I23: Club | J23: Caps | K23: Goals | L23: Serious_injury
A29: SELECT | B29: "Tab2_Goalkeeper", ID, "M", INITCAP(FirstName), UPPER(LastName), INITCAP(Position), UPPER(Country_Origin),
B30: NULL, NULL, NULL, NULL, NULL
A31: FROM | B31: Tab2_Goalkeeper
A32: WHERE …
A34: UNION
A37: SELECT | B37: "Tab3_TOP10_JoueursFoot", ID, "M", INITCAP(Prénom), UPPER(NOM), INITCAP(Poste), UPPER(TRANSLATECOUNTRY(Pays2Naissance), Année2Naissance,
B38: NULL, NULL, NULL, NULL
A39: FROM | B39: Tab3_TOP10_JoueursFoot
A40: WHERE …
A42: UNION
A45: SELECT | B45: "Tab4_BlessuresJoueurs", NULL, "M", INITCAP(Prénom), UPPER(NOM), NULL, NULL, NULL, NULL,
B46: NULL, NULL, INITCAP(Type2Blessure_Grave)
A47: FROM | B47: Tab4_BlessuresJoueurs
A48: WHERE …
A50: UNION
A53: SELECT | B53: "Tab5_JoueusesFoot", NULL, "F", INITCAP(EXTRACTFN(Name)), UPPER(EXTRACTLN(Name)), INITCAP(Position), UPPER(Nationality), EXTRACTY(DateOfBirth),
B54: Club, Caps, Goals, NULL
A55: FROM | B55: Tab5_JoueusesFoot
A56: WHERE …
A58: UNION ALL
A60: SELECT | B60: "Tab1_Joueurs", ID, "M", INITCAP(Prénom), UPPER(NOM), INITCAP(TRANSLATEPOSTE(Poste)), UPPER(TRANSLATECOUNTRY(PaysdOrigine), Année2Naissance,
B61: NULL, NULL, NULL, NULL
A62: FROM | B62: Tab1_Joueurs
A63: WHERE …
A64: ;

Sheet BD-DWH
A1: DataSource | B1: ID_footballer | C1: Gender | D1: FirstName | E1: LastName | F1: Position | G1: CountryOfOrigin | H1: YearOfBirth | I1: Club | J1: Caps | K1: Goals | L1: Serious_injury
A2: Tab2_Goalkeeper | B2: GERGK01 | C2: M | D2: Manuel | E2: NEUER | F2: Goalkeeper | G2: GERMANY | H2: NULL | I2: NULL | J2: NULL | K2: NULL | L2: NULL
A3: Tab2_Goalkeeper | B3: GERGK02 | C3: M | D3: Marc-André | E3: TER STEGEN | F3: Goalkeeper | G3: GERMANY | H3: NULL | I3: NULL | J3: NULL | K3: NULL | L3: NULL
A4: Tab2_Goalkeeper | B4: ENGGK03 | C4: M | D4: Nick | E4: POPE | F4: Goalkeeper | G4: ENGLAND | H4: NULL | I4: NULL | J4: NULL | K4: NULL | L4: NULL
A5: Tab2_Goalkeeper | B5: ENGGK04 | C5: M | D5: Jordan | E5: PICKFORD | F5: Goalkeeper | G5: ENGLAND | H5: NULL | I5: NULL | J5: NULL | K5: NULL | L5: NULL
A6: Tab2_Goalkeeper | B6: ENGGK05 | C6: M | D6: Aaron | E6: RAMSDALE | F6: Goalkeeper | G6: ENGLAND | H6: NULL | I6: NULL | J6: NULL | K6: NULL | L6: NULL
A7: Tab2_Goalkeeper | B7: ARGGK06 | C7: M | D7: Emiliano | E7: MARTÍNEZ | F7: Goalkeeper | G7: ARGENTINA | H7: NULL | I7: NULL | J7: NULL | K7: NULL | L7: NULL
A8: Tab2_Goalkeeper | B8: BELGK07 | C8: M | D8: Thibaut | E8: COURTOIS | F8: Goalkeeper | G8: BELGIUM | H8: NULL | I8: NULL | J8: NULL | K8: NULL | L8: NULL
A9: Tab2_Goalkeeper | B9: BRAGK08 | C9: M | D9: Becker | E9: ALISSON | F9: Goalkeeper | G9: BRAZIL | H9: NULL | I9: NULL | J9: NULL | K9: NULL | L9: NULL
A10: Tab2_Goalkeeper | B10: BRAGK09 | C10: M | D10: Moraes | E10: EDERSON | F10: Goalkeeper | G10: BRAZIL | H10: NULL | I10: NULL | J10: NULL | K10: NULL | L10: NULL
A11: Tab2_Goalkeeper | B11: CAMGK10 | C11: M | D11: André | E11: ONANA | F11: Goalkeeper | G11: CAMEROON | H11: NULL | I11: NULL | J11: NULL | K11: NULL | L11: NULL
A12: Tab2_Goalkeeper | B12: COSGK11 | C12: M | D12: Keylor | E12: NAVAS | F12: Goalkeeper | G12: COSTA RICA | H12: NULL | I12: NULL | J12: NULL | K12: NULL | L12: NULL
... A21: Tab2_Goalkeeper | B21: UKRGK20 | C21: M | D21: Anatoliy | E21: TRUBIN | F21: Goalkeeper | G21: UKRAINE | H21: NULL | I21: NULL | J21: NULL | K21: NULL | L21: NULL
A22: Tab3_TOP10_JoueursFoot | B22: 1 | C22: M | D22: Alfredo | E22: DI STÉFANO | F22: Attaquant | G22: ARGENTINA | H22: 1926 | I22: NULL | J22: NULL | K22: NULL | L22: NULL
A23: Tab3_TOP10_JoueursFoot | B23: 2 | C23: M | D23: Lev | E23: YASHIN | F23: Gardien | G23: RUSSIA | H23: 1929 | I23: NULL | J23: NULL | K23: NULL | L23: NULL
A24: Tab3_TOP10_JoueursFoot | B24: 3 | C24: M | D24: Gordon | E24: BANKS | F24: Gardien | G24: ENGLAND | H24: 1937 | I24: NULL | J24: NULL | K24: NULL | L24: NULL
A25: Tab3_TOP10_JoueursFoot | B25: 4 | C25: M | D25: Edson | E25: PELÉ | F25: Attaquant | G25: BRAZIL | H25: 1940 | I25: NULL | J25: NULL | K25: NULL | L25: NULL
A26: Tab3_TOP10_JoueursFoot | B26: 5 | C26: M | D26: Dino | E26: ZOFF | F26: Gardien | G26: ITALY | H26: 1942 | I26: NULL | J26: NULL | K26: NULL | L26: NULL
A27: Tab3_TOP10_JoueursFoot | B27: 6 | C27: M | D27: Franz | E27: BECKENBAUER | F27: Défenseur | G27: GERMANY | H27: 1945 | I27: NULL | J27: NULL | K27: NULL | L27: NULL
A28: Tab3_TOP10_JoueursFoot | B28: 7 | C28: M | D28: Johan | E28: CRUYFF | F28: Milieu | G28: NETHERLANDS | H28: 1947 | I28: NULL | J28: NULL | K28: NULL | L28: NULL
A29: Tab3_TOP10_JoueursFoot | B29: 8 | C29: M | D29: Luis | E29: ARCONADA | F29: Gardien | G29: SPAIN | H29: 1954 | I29: NULL | J29: NULL | K29: NULL | L29: NULL
A30: Tab3_TOP10_JoueursFoot | B30: 9 | C30: M | D30: Michel | E30: PLATINI | F30: Milieu | G30: FRANCE | H30: 1955 | I30: NULL | J30: NULL | K30: NULL | L30: NULL
A31: Tab3_TOP10_JoueursFoot | B31: 10 | C31: M | D31: Diego | E31: MARADONA | F31: Attaquant | G31: ARGENTINA | H31: 1960 | I31: NULL | J31: NULL | K31: NULL | L31: NULL
A32: Tab3_TOP10_JoueursFoot | B32: 11 | C32: M | D32: Peter | E32: SCHMEICHEL | F32: Gardien | G32: DENMARK | H32: 1963 | I32: NULL | J32: NULL | K32: NULL | L32: NULL
A33: Tab3_TOP10_JoueursFoot | B33: 12 | C33: M | D33: Cláudio | E33: TAFFAREL | F33: Gardien | G33: BRAZIL | H33: 1966 | I33: NULL | J33: NULL | K33: NULL | L33: NULL
... A41: Tab3_TOP10_JoueursFoot | B41: 20 | C41: M | D41: Lionel | E41: MESSI | F41: Attaquant | G41: ARGENTINA | H41: 1987 | I41: NULL | J41: NULL | K41: NULL | L41: NULL
A42: Tab4_BlessuresJoueurs | B42: NULL | C42: M | D42: =PROPER(Tab4_BlessuresJoueurs!A2) -> Rodri | E42: =UPPER(Tab4_BlessuresJoueurs!B2) -> HERNÁNDEZ | F42: NULL | G42: NULL | H42: NULL | I42: NULL | J42: NULL | K42: NULL | L42: Rupture du ligament croisé du genou
A43: Tab4_BlessuresJoueurs | B43: NULL | C43: M | D43: =PROPER(Tab4_BlessuresJoueurs!A3) -> Dani | E43: =UPPER(Tab4_BlessuresJoueurs!B3) -> CARVAJAL | F43: NULL | G43: NULL | H43: NULL | I43: NULL | J43: NULL | K43: NULL | L43: Rupture du ligament croisé du genou
A44: Tab4_BlessuresJoueurs | B44: NULL | C44: M | D44: =PROPER(Tab4_BlessuresJoueurs!A4) -> Eder | E44: =UPPER(Tab4_BlessuresJoueurs!B4) -> MILITÃO | F44: NULL | G44: NULL | H44: NULL | I44: NULL | J44: NULL | K44: NULL | L44: Rupture du ligament croisé du genou
A45: Tab4_BlessuresJoueurs | B45: NULL | C45: M | D45: =PROPER(Tab4_BlessuresJoueurs!A5) -> Mauro | E45: =UPPER(Tab4_BlessuresJoueurs!B5) -> ICARDI | F45: NULL | G45: NULL | H45: NULL | I45: NULL | J45: NULL | K45: NULL | L45: Rupture du ligament croisé du genou
A46: Tab4_BlessuresJoueurs | B46: NULL | C46: M | D46: =PROPER(Tab4_BlessuresJoueurs!A6) -> Gianluca | E46: =UPPER(Tab4_BlessuresJoueurs!B6) -> SCAMACCA | F46: NULL | G46: NULL | H46: NULL | I46: NULL | J46: NULL | K46: NULL | L46: Rupture du ligament croisé du genou
A47: Tab4_BlessuresJoueurs | B47: NULL | C47: M | D47: =PROPER(Tab4_BlessuresJoueurs!A7) -> Gleison | E47: =UPPER(Tab4_BlessuresJoueurs!B7) -> BREMER | F47: NULL | G47: NULL | H47: NULL | I47: NULL | J47: NULL | K47: NULL | L47: Rupture du ligament croisé du genou
A48: Tab4_BlessuresJoueurs | B48: NULL | C48: M | D48: =PROPER(Tab4_BlessuresJoueurs!A8) -> Alessandro | E48: =UPPER(Tab4_BlessuresJoueurs!B8) -> FLORENZI | F48: NULL | G48: NULL | H48: NULL | I48: NULL | J48: NULL | K48: NULL | L48: Rupture du ligament croisé du genou
A49: Tab4_BlessuresJoueurs | B49: NULL | C49: M | D49: =PROPER(Tab4_BlessuresJoueurs!A9) -> Sven | E49: =UPPER(Tab4_BlessuresJoueurs!B9) -> BOTMAN | F49: NULL | G49: NULL | H49: NULL | I49: NULL | J49: NULL | K49: NULL | L49: Rupture du ligament croisé du genou
A50: Tab4_BlessuresJoueurs | B50: NULL | C50: M | D50: =PROPER(Tab4_BlessuresJoueurs!A10) -> Duván | E50: =UPPER(Tab4_BlessuresJoueurs!B10) -> ZAPATA | F50: NULL | G50: NULL | H50: NULL | I50: NULL | J50: NULL | K50: NULL | L50: Rupture du ligament croisé du genou
A51: Tab4_BlessuresJoueurs | B51: NULL | C51: M | D51: =PROPER(Tab4_BlessuresJoueurs!A11) -> Terem | E51: =UPPER(Tab4_BlessuresJoueurs!B11) -> MOFFI | F51: NULL | G51: NULL | H51: NULL | I51: NULL | J51: NULL | K51: NULL | L51: Rupture du ligament croisé
A52: Tab4_BlessuresJoueurs | B52: NULL | C52: M | D52: =PROPER(Tab4_BlessuresJoueurs!A12) -> Tiago | E52: =UPPER(Tab4_BlessuresJoueurs!B12) -> SANTOS | F52: NULL | G52: NULL | H52: NULL | I52: NULL | J52: NULL | K52: NULL | L52: Rupture du ligament croisé
A53: Tab4_BlessuresJoueurs | B53: NULL | C53: M | D53: =PROPER(Tab4_BlessuresJoueurs!A13) -> Moïse | E53: =UPPER(Tab4_BlessuresJoueurs!B13) -> SAHI DION | F53: NULL | G53: NULL | H53: NULL | I53: NULL | J53: NULL | K53: NULL | L53: Rupture du tendon d'Achille
... A93: Tab4_BlessuresJoueurs | B93: NULL | C93: M | D93: =PROPER(Tab4_BlessuresJoueurs!A53) -> Tino | E93: =UPPER(Tab4_BlessuresJoueurs!B53) -> KADEWERE | F93: NULL | G93: NULL | H93: NULL | I93: NULL | J93: NULL | K93: NULL | L93: Blessure à la cuisse
A94: Tab5_JoueusesFoot | B94: NULL | C94: F | D94: Alex | E94: MORGAN | F94: Forward | G94: USA | H94: 1989 | I94: San Diego Wave | J94: 200 | K94: 120 | L94: NULL
...

Sheet BD-DWH (2)
A1: DataSource | B1: ID_footballer | C1: Gender | D1: FirstName | E1: LastName | F1: Position | G1: CountryOfOrigin | H1: YearOfBirth | I1: Club | J1: Caps | K1: Goals | L1: Serious_injury
A2: Tab1_Joueurs | B2: 1993AutAla | C2: M | D2: David | E2: ALABA | F2: Defender | G2: AUSTRIA | H2: 1993 | I2: NULL | J2: NULL | K2: NULL | L2: NULL
A3: Tab1_Joueurs | B3: 1989EspAlb | C3: M | D3: Jordi | E3: ALBA | F3: Defender | G3: SPAIN | H3: 1989 | I3: NULL | J3: NULL | K3: NULL | L3: NULL
A4: Tab1_Joueurs | B4: 1999AngAle | C4: M | D4: Trent | E4: ALEXANDER-ARNOLD | F4: Defender | G4: ENGLAND | H4: 1999 | I4: NULL | J4: NULL | K4: NULL | L4: NULL
A5: Tab2_Goalkeeper | B5: BRAGK08 | C5: M | D5: Becker | E5: ALISSON | F5: Goalkeeper | G5: BRAZIL | H5: NULL | I5: NULL | J5: NULL | K5: NULL | L5: NULL
A6: Tab1_Joueurs | B6: 1992BréAli | C6: M | D6: Becker | E6: ALISSON | F6: Goalkeeper | G6: BRAZIL | H6: 1992 | I6: NULL | J6: NULL | K6: NULL | L6: NULL
A7: Tab1_Joueurs | B7: 2002ArgAlm | C7: M | D7: Thiago | E7: ALMADA | F7: Midfielder | G7: ARGENTINA | H7: 2002 | I7: NULL | J7: NULL | K7: NULL | L7: NULL
A8: Tab1_Joueurs | B8: 2003ItaAnt | C8: M | D8: Antonio | E8: ANTONIO | F8: Defender | G8: ITALY | H8: 2003 | I8: NULL | J8: NULL | K8: NULL | L8: NULL
A9: Tab3_TOP10_JoueursFoot | B9: 8 | C9: M | D9: Luis | E9: ARCONADA | F9: Gardien | G9: SPAIN | H9: 1954 | I9: NULL | J9: NULL | K9: NULL | L9: NULL
A10: Tab1_Joueurs | B10: 2004EspBal | C10: M | D10: Alejandro | E10: BALDE | F10: Defender | G10: SPAIN | H10: 2004 | I10: NULL | J10: NULL | K10: NULL | L10: NULL
A11: Tab1_Joueurs | B11: 1990PayBal | C11: M | D11: Gareth | E11: BALE | F11: Forward | G11: WALES | H11: 1990 | I11: NULL | J11: NULL | K11: NULL | L11: NULL
A12: Tab4_BlessuresJoueurs | B12: NULL | C12: M | D12: =PROPER(Tab4_BlessuresJoueurs!A26) -> Folarin | E12: =UPPER(Tab4_BlessuresJoueurs!B26) -> BALOGUN | F12: NULL | G12: NULL | H12: NULL | I12: NULL | J12: NULL | K12: NULL | L12: Blessure de l'épaule
A13: Tab1_Joueurs | B13: 2002ÉtaBal | C13: M | D13: Folarin | E13: BALOGUN | F13: Forward | G13: UNITED-STATES | H13: 2002 | I13: NULL | J13: NULL | K13: NULL | L13: NULL
A14: Tab3_TOP10_JoueursFoot | B14: 3 | C14: M | D14: Gordon | E14: BANKS | F14: Gardien | G14: ENGLAND | H14: 1937 | I14: NULL | J14: NULL | K14: NULL | L14: NULL
A15: Tab1_Joueurs | B15: 1997ItaBar | C15: M | D15: Nicolò | E15: BARELLA | F15: Midfielder | G15: ITALY | H15: 1997 | I15: NULL | J15: NULL | K15: NULL | L15: NULL
A16: Tab3_TOP10_JoueursFoot | B16: 6 | C16: M | D16: Franz | E16: BECKENBAUER | F16: Défenseur | G16: GERMANY | H16: 1945 | I16: NULL | J16: NULL | K16: NULL | L16: NULL
A17: Tab1_Joueurs | B17: 2003AngBel | C17: M | D17: Jude | E17: BELLINGHAM | F17: Midfielder | G17: ENGLAND | H17: 2003 | I17: NULL | J17: NULL | K17: NULL | L17: NULL
A18: Tab4_BlessuresJoueurs | B18: NULL | C18: M | D18: =PROPER(Tab4_BlessuresJoueurs!A20) -> Nabil | E18: =UPPER(Tab4_BlessuresJoueurs!B20) -> BENTALEB | F18: NULL | G18: NULL | H18: NULL | I18: NULL | J18: NULL | K18: NULL | L18: Problème de cœur
A19: Tab1_Joueurs | B19: 1988FraBen | C19: M | D19: Karim | E19: BENZEMA | F19: Forward | G19: FRANCE | H19: 1988 | I19: NULL | J19: NULL | K19: NULL | L19: NULL
A20: Tab1_Joueurs | B20: 1994PorBer | C20: M | D20: Silva | E20: BERNARDO | F20: Midfielder | G20: PORTUGAL | H20: 1994 | I20: NULL | J20: NULL | K20: NULL | L20: NULL
A21: Tab1_Joueurs | B21: 1987ItaBon | C21: M | D21: Leonardo | E21: BONUCCI | F21: Defender | G21: ITALY | H21: 1987 | I21: NULL | J21: NULL | K21: NULL | L21: NULL
A22: Tab4_BlessuresJoueurs | B22: NULL | C22: M | D22: =PROPER(Tab4_BlessuresJoueurs!A9) -> Sven | E22: =UPPER(Tab4_BlessuresJoueurs!B9) -> BOTMAN | F22: NULL | G22: NULL | H22: NULL | I22: NULL | J22: NULL | K22: NULL | L22: Rupture du ligament croisé du genou
A23: Tab4_BlessuresJoueurs | B23: NULL | C23: M | D23: =PROPER(Tab4_BlessuresJoueurs!A44) -> Sven | E23: =UPPER(Tab4_BlessuresJoueurs!B44) -> BOTMAN | F23: NULL | G23: NULL | H23: NULL | I23: NULL | J23: NULL | K23: NULL | L23: Rupture des ligaments croisés du genou
A24: Tab4_BlessuresJoueurs | B24: NULL | C24: M | D24: =PROPER(Tab4_BlessuresJoueurs!A7) -> Gleison | E24: =UPPER(Tab4_BlessuresJoueurs!B7) -> BREMER | F24: NULL | G24: NULL | H24: NULL | I24: NULL | J24: NULL | K24: NULL | L24: Rupture du ligament croisé du genou
A25: Tab4_BlessuresJoueurs | B25: NULL | C25: M | D25: =PROPER(Tab4_BlessuresJoueurs!A42) -> Gleison | E25: =UPPER(Tab4_BlessuresJoueurs!B42) -> BREMER | F25: NULL | G25: NULL | H25: NULL | I25: NULL | J25: NULL | K25: NULL | L25: Rupture des ligaments croisés du genou
A26: Tab5_JoueusesFoot | B26: NULL | C26: F | D26: Lucy | E26: BRONZE | F26: Defender | G26: ENGLAND | H26: 1991 | I26: Barcelona | J26: 130 | K26: 12 | L26: NULL
A27: Tab4_BlessuresJoueurs | B27: NULL | C27: M | D27: =PROPER(Tab4_BlessuresJoueurs!A31) -> Nathan | E27: =UPPER(Tab4_BlessuresJoueurs!B31) -> BUAYI-KIALA | F27: NULL | G27: NULL | H27: NULL | I27: NULL | J27: NULL | K27: NULL | L27: Blessure au ligament croisé
A28: Tab5_JoueusesFoot | B28: NULL | C28: F | D28: Kadeisha | E28: BUCHANAN | F28: Defender | G28: CANADA | H28: 1995 | I28: Chelsea | J28: 135 | K28: 10 | L28: NULL
A29: Tab3_TOP10_JoueursFoot | B29: 16 | C29: M | D29: Gianluigi | E29: BUFFON | F29: Gardien | G29: ITALY | H29: 1978 | I29: NULL | J29: NULL | K29: NULL | L29: NULL
A30: Tab1_Joueurs | B30: 1988EspBus | C30: M | D30: Sergio | E30: BUSQUETS | F30: Midfielder | G30: SPAIN | H30: 1988 | I30: NULL | J30: NULL | K30: NULL | L30: NULL
A31: Tab1_Joueurs | B31: 2002CôtCai | C31: M | D31: Moisés | E31: CAICEDO | F31: Midfielder | G31: IVORY-COAST | H31: 2002 | I31: NULL | J31: NULL | K31: NULL | L31: NULL
A32: Tab1_Joueurs | B32: 2003FraCam | C32: M | D32: Eduardo | E32: CAMAVINGA | F32: Midfielder | G32: FRANCE | H32: 2003 | I32: NULL | J32: NULL | K32: NULL | L32: NULL
A33: Tab4_BlessuresJoueurs | B33: NULL | C33: M | D33: =PROPER(Tab4_BlessuresJoueurs!A30) -> Valentín | E33: =UPPER(Tab4_BlessuresJoueurs!B30) -> CARBONI | F33: NULL | G33: NULL | H33: NULL | I33: NULL | J33: NULL | K33: NULL | L33: Rupture du ligament croisé
A34: Tab4_BlessuresJoueurs | B34: NULL | C34: M | D34: =PROPER(Tab4_BlessuresJoueurs!A3) -> Dani | E34: =UPPER(Tab4_BlessuresJoueurs!B3) -> CARVAJAL | F34: NULL | G34: NULL | H34: NULL | I34: NULL | J34: NULL | K34: NULL | L34: Rupture du ligament croisé du genou
A35: Tab4_BlessuresJoueurs | B35: NULL | C35: M | D35: =PROPER(Tab4_BlessuresJoueurs!A38) -> Dani | E35: =UPPER(Tab4_BlessuresJoueurs!B38) -> CARVAJAL | F35: NULL | G35: NULL | H35: NULL | I35: NULL | J35: NULL | K35: NULL | L35: Rupture des ligaments croisés du genou
A36: Tab5_JoueusesFoot | B36: NULL | C36: F | D36: Delphine | E36: CASCARINO | F36: Winger | G36: FRANCE | H36: 1997 | I36: Olympique Lyonnais | J36: 95 | K36: 25 | L36: NULL
A37: Tab1_Joueurs | B37: 1992BréCas | C37: M | D37: Carlos | E37: CASEMIRO | F37: Midfielder | G37: BRAZIL | H37: 1992 | I37: NULL | J37: NULL | K37: NULL | L37: NULL
A38: Tab3_TOP10_JoueursFoot | B38: 17 | C38: M | D38: Iker | E38: CASILLAS | F38: Gardien | G38: SPAIN | H38: 1981 | I38: NULL | J38: NULL | K38: NULL | L38: NULL
A39: Tab4_BlessuresJoueurs | B39: NULL | C39: M | D39: =PROPER(Tab4_BlessuresJoueurs!A35) -> José Luis | E39: =UPPER(Tab4_BlessuresJoueurs!B35) -> CATALÁ | F39: NULL | G39: NULL | H39: NULL | I39: NULL | J39: NULL | K39: NULL | L39: Rupture du ligament croisé antérieur et lésion du ménisque externe de la rodilla droite
A40: Tab1_Joueurs | B40: 1988UruCav | C40: M | D40: Edinson | E40: CAVANI | F40: Forward | G40: URUGUAY | H40: 1988 | I40: NULL | J40: NULL | K40: NULL | L40: NULL
...

Sheet BD-DWH (3)
A1: ID_footballer | B1: Gender | C1: FirstName | D1: LastName | E1: Position | F1: CountryOfOrigin | G1: YearOfBirth | I1: ', '
A2: 1 | B2: F | C2: Carli | D2: LLOYD | E2: Midfielder | F2: UNITED-STATES-OF-AMERICA | G2: 1982 | I2: =CONCATENATE("INSERT INTO T_Dim_J VALUES ('",A2,$I$1,B2,$I$1,C2,$I$1,D2,$I$1,E2,$I$1,F2,$I$1,G2,"');") -> INSERT INTO T_Dim_J VALUES ('1', 'F', 'Carli', 'LLOYD', 'Midfielder', 'UNITED-STATES-OF-AMERICA', '1982');
A3: 2 | B3: F | C3: Christine | D3: SINCLAIR | E3: Forward | F3: CANADA | G3: 1983 | I3: =CONCATENATE("INSERT INTO T_Dim_J VALUES ('",A3,$I$1,B3,$I$1,C3,$I$1,D3,$I$1,E3,$I$1,F3,$I$1,G3,"');") -> INSERT INTO T_Dim_J VALUES ('2', 'F', 'Christine', 'SINCLAIR', 'Forward', 'CANADA', '1983');
A4: 3 | B4: F | C4: Megan | D4: RAPINOE | E4: Winger | F4: UNITED-STATES-OF-AMERICA | G4: 1985 | I4: =CONCATENATE("INSERT INTO T_Dim_J VALUES ('",A4,$I$1,B4,$I$1,C4,$I$1,D4,$I$1,E4,$I$1,F4,$I$1,G4,"');") -> INSERT INTO T_Dim_J VALUES ('3', 'F', 'Megan', 'RAPINOE', 'Winger', 'UNITED-STATES-OF-AMERICA', '1985');
A5: 4 | B5: F | C5: Marta | D5: VIEIRA-DA-SILVA | E5: Forward | F5: BRAZIL | G5: 1986 | I5: =CONCATENATE("INSERT INTO T_Dim_J VALUES ('",A5,$I$1,B5,$I$1,C5,$I$1,D5,$I$1,E5,$I$1,F5,$I$1,G5,"');") -> INSERT INTO T_Dim_J VALUES ('4', 'F', 'Marta', 'VIEIRA-DA-SILVA', 'Forward', 'BRAZIL', '1986');
A6: 5 | B6: F | C6: Tobin | D6: HEATH | E6: Winger | F6: UNITED-STATES-OF-AMERICA | G6: 1988 | I6: =CONCATENATE("INSERT INTO T_Dim_J VALUES ('",A6,$I$1,B6,$I$1,C6,$I$1,D6,$I$1,E6,$I$1,F6,$I$1,G6,"');") -> INSERT INTO T_Dim_J VALUES ('5', 'F', 'Tobin', 'HEATH', 'Winger', 'UNITED-STATES-OF-AMERICA', '1988');
A7: 6 | B7: F | C7: Amandine | D7: HENRY | E7: Midfielder | F7: FRANCE | G7: 1989 | I7: =CONCATENATE("INSERT INTO T_Dim_J VALUES ('",A7,$I$1,B7,$I$1,C7,$I$1,D7,$I$1,E7,$I$1,F7,$I$1,G7,"');") -> INSERT INTO T_Dim_J VALUES ('6', 'F', 'Amandine', 'HENRY', 'Midfielder', 'FRANCE', '1989');
A8: 7 | B8: F | C8: Alex | D8: MORGAN | E8: Forward | F8: UNITED-STATES-OF-AMERICA | G8: 1989 | I8: =CONCATENATE("INSERT INTO T_Dim_J VALUES ('",A8,$I$1,B8,$I$1,C8,$I$1,D8,$I$1,E8,$I$1,F8,$I$1,G8,"');") -> INSERT INTO T_Dim_J VALUES ('7', 'F', 'Alex', 'MORGAN', 'Forward', 'UNITED-STATES-OF-AMERICA', '1989');
A9: 8 | B9: F | C9: Saki | D9: KUMAGAI | E9: Defender | F9: JAPAN | G9: 1990 | I9: =CONCATENATE("INSERT INTO T_Dim_J VALUES ('",A9,$I$1,B9,$I$1,C9,$I$1,D9,$I$1,E9,$I$1,F9,$I$1,G9,"');") -> INSERT INTO T_Dim_J VALUES ('8', 'F', 'Saki', 'KUMAGAI', 'Defender', 'JAPAN', '1990');
A10: 9 | B10: F | C10: Wendie | D10: RENARD | E10: Defender | F10: FRANCE | G10: 1990 | I10: =CONCATENATE("INSERT INTO T_Dim_J VALUES ('",A10,$I$1,B10,$I$1,C10,$I$1,D10,$I$1,E10,$I$1,F10,$I$1,G10,"');") -> INSERT INTO T_Dim_J VALUES ('9', 'F', 'Wendie', 'RENARD', 'Defender', 'FRANCE', '1990');
A11: 10 | B11: F | C11: Lucy | D11: BRONZE | E11: Defender | F11: ENGLAND | G11: 1991 | I11: =CONCATENATE("INSERT INTO T_Dim_J VALUES ('",A11,$I$1,B11,$I$1,C11,$I$1,D11,$I$1,E11,$I$1,F11,$I$1,G11,"');") -> INSERT INTO T_Dim_J VALUES ('10', 'F', 'Lucy', 'BRONZE', 'Defender', 'ENGLAND', '1991');
A12: 11 | B12: F | C12: Irene | D12: PAREDES | E12: Defender | F12: SPAIN | G12: 1991 | I12: =CONCATENATE("INSERT INTO T_Dim_J VALUES ('",A12,$I$1,B12,$I$1,C12,$I$1,D12,$I$1,E12,$I$1,F12,$I$1,G12,"');") -> INSERT INTO T_Dim_J VALUES ('11', 'F', 'Irene', 'PAREDES', 'Defender', 'SPAIN', '1991');
A13: 12 | B13: F | C13: Ji | D13: SO-YUN | E13: Midfielder | F13: SOUTH-KOREA | G13: 1991 | I13: =CONCATENATE("INSERT INTO T_Dim_J VALUES ('",A13,$I$1,B13,$I$1,C13,$I$1,D13,$I$1,E13,$I$1,F13,$I$1,G13,"');") -> INSERT INTO T_Dim_J VALUES ('12', 'F', 'Ji', 'SO-YUN', 'Midfielder', 'SOUTH-KOREA', '1991');
... A203: 202 | B203: M | C203: Lamine | D203: YAMAL | E203: Forward | F203: SPAIN | G203: 2008 | I203: =CONCATENATE("INSERT INTO T_Dim_J VALUES ('",A203,$I$1,B203,$I$1,C203,$I$1,D203,$I$1,E203,$I$1,F203,$I$1,G203,"');") -> INSERT INTO T_Dim_J VALUES ('202', 'M', 'Lamine', 'YAMAL', 'Forward', 'SPAIN', '2008');
A204: 203 | B204: M | C204: Nabil | D204: BENTALEB | E204: NULL | F204: NULL | G204: NULL | I204: =CONCATENATE("INSERT INTO T_Dim_J VALUES ('",A204,$I$1,B204,$I$1,C204,$I$1,D204,$I$1,E204,$I$1,F204,$I$1,G204,"');") -> INSERT INTO T_Dim_J VALUES ('203', 'M', 'Nabil', 'BENTALEB', 'NULL', 'NULL', 'NULL');
A205: 204 | B205: M | C205: Sven | D205: BOTMAN | E205: NULL | F205: NULL | G205: NULL | I205: =CONCATENATE("INSERT INTO T_Dim_J VALUES ('",A205,$I$1,B205,$I$1,C205,$I$1,D205,$I$1,E205,$I$1,F205,$I$1,G205,"');") -> INSERT INTO T_Dim_J VALUES ('204', 'M', 'Sven', 'BOTMAN', 'NULL', 'NULL', 'NULL');
A206: 205 | B206: M | C206: Gleison | D206: BREMER | E206: NULL | F206: NULL | G206: NULL | I206: =CONCATENATE("INSERT INTO T_Dim_J VALUES ('",A206,$I$1,B206,$I$1,C206,$I$1,D206,$I$1,E206,$I$1,F206,$I$1,G206,"');") -> INSERT INTO T_Dim_J VALUES ('205', 'M', 'Gleison', 'BREMER', 'NULL', 'NULL', 'NULL');
A207: 206 | B207: M | C207: Nathan | D207: BUAYI-KIALA | E207: NULL | F207: NULL | G207: NULL | I207: =CONCATENATE("INSERT INTO T_Dim_J VALUES ('",A207,$I$1,B207,$I$1,C207,$I$1,D207,$I$1,E207,$I$1,F207,$I$1,G207,"');") -> INSERT INTO T_Dim_J VALUES ('206', 'M', 'Nathan', 'BUAYI-KIALA', 'NULL', 'NULL', 'NULL');
A208: 207 | B208: M | C208: Valentín | D208: CARBONI | E208: NULL | F208: NULL | G208: NULL | I208: =CONCATENATE("INSERT INTO T_Dim_J VALUES ('",A208,$I$1,B208,$I$1,C208,$I$1,D208,$I$1,E208,$I$1,F208,$I$1,G208,"');") -> INSERT INTO T_Dim_J VALUES ('207', 'M', 'Valentín', 'CARBONI', 'NULL', 'NULL', 'NULL');
A209: 208 | B209: M | C209: Dani | D209: CARVAJAL | E209: NULL | F209: NULL | G209: NULL | I209: =CONCATENATE("INSERT INTO T_Dim_J VALUES ('",A209,$I$1,B209,$I$1,C209,$I$1,D209,$I$1,E209,$I$1,F209,$I$1,G209,"');") -> INSERT INTO T_Dim_J VALUES ('208', 'M', 'Dani', 'CARVAJAL', 'NULL', 'NULL', 'NULL');
A210: 209 | B210: M | C210: José Luis | D210: CATALÁ | E210: NULL | F210: NULL | G210: NULL | I210: =CONCATENATE("INSERT INTO T_Dim_J VALUES ('",A210,$I$1,B210,$I$1,C210,$I$1,D210,$I$1,E210,$I$1,F210,$I$1,G210,"');") -> INSERT INTO T_Dim_J VALUES ('209', 'M', 'José Luis', 'CATALÁ', 'NULL', 'NULL', 'NULL');
A211: 210 | B211: M | C211: Sidiki | D211: CHÉRIF | E211: NULL | F211: NULL | G211: NULL | I211: =CONCATENATE("INSERT INTO T_Dim_J VALUES ('",A211,$I$1,B211,$I$1,C211,$I$1,D211,$I$1,E211,$I$1,F211,$I$1,G211,"');") -> INSERT INTO T_Dim_J VALUES ('210', 'M', 'Sidiki', 'CHÉRIF', 'NULL', 'NULL', 'NULL');
A212: 211 | B212: M | C212: Lasso | D212: COULIBALY | E212: NULL | F212: NULL | G212: NULL | I212: =CONCATENATE("INSERT INTO T_Dim_J VALUES ('",A212,$I$1,B212,$I$1,C212,$I$1,D212,$I$1,E212,$I$1,F212,$I$1,G212,"');") -> INSERT INTO T_Dim_J VALUES ('211', 'M', 'Lasso', 'COULIBALY', 'NULL', 'NULL', 'NULL');
A213: 212 | B213: M | C213: Matias | D213: FERNANDEZ-PARDO | E213: NULL | F213: NULL | G213: NULL | I213: =CONCATENATE("INSERT INTO T_Dim_J VALUES ('",A213,$I$1,B213,$I$1,C213,$I$1,D213,$I$1,E213,$I$1,F213,$I$1,G213,"');") -> INSERT INTO T_Dim_J VALUES ('212', 'M', 'Matias', 'FERNANDEZ-PARDO', 'NULL', 'NULL', 'NULL');
A214: 213 | B214: M | C214: Alessandro | D214: FLORENZI | E214: NULL | F214: NULL | G214: NULL | I214: =CONCATENATE("INSERT INTO T_Dim_J VALUES ('",A214,$I$1,B214,$I$1,C214,$I$1,D214,$I$1,E214,$I$1,F214,$I$1,G214,"');") -> INSERT INTO T_Dim_J VALUES ('213', 'M', 'Alessandro', 'FLORENZI', 'NULL', 'NULL', 'NULL');
A215: 214 | B215: M | C215: José | D215: GRAGERA | E215: NULL | F215: NULL | G215: NULL | I215: =CONCATENATE("INSERT INTO T_Dim_J VALUES ('",A215,$I$1,B215,$I$1,C215,$I$1,D215,$I$1,E215,$I$1,F215,$I$1,G215,"');") -> INSERT INTO T_Dim_J VALUES ('214', 'M', 'José', 'GRAGERA', 'NULL', 'NULL', 'NULL');
... A234: 233 | B234: M | C234: Duván | D234: ZAPATA | E234: NULL | F234: NULL | G234: NULL | I234: =CONCATENATE("INSERT INTO T_Dim_J VALUES ('",A234,$I$1,B234,$I$1,C234,$I$1,D234,$I$1,E234,$I$1,F234,$I$1,G234,"');") -> INSERT INTO T_Dim_J VALUES ('233', 'M', 'Duván', 'ZAPATA', 'NULL', 'NULL', 'NULL');

Sheet Stats_J
A1: R1, R2, R3 : Nombre de joueuses/joueurs
A2: Gender | B2: Nombre
A3: F | B3: 30
A4: M | B4: 203
A5: Total général | B5: 233
A8: R4 : Nombre de joueuses/joueurs par pays
A9: Nombre | B9: Gender
A10: Country | B10: F | C10: M | D10: Total général
A11: ALGERIA | C11: 1 | D11: 1
A12: ARGENTINA | C12: 11 | D12: 11
A13: AUSTRALIA | B13: 1 | D13: 1
A14: AUSTRIA | C14: 1 | D14: 1
A15: BELGIUM | C15: 4 | D15: 4
A16: BRAZIL | B16: 1 | C16: 16 | D16: 17
A17: CAMEROON | C17: 2 | D17: 2
A18: CANADA | B18: 2 | C18: 1 | D18: 3
A19: COSTA-RICA | C19: 1 | D19: 1
A20: CROATIA | C20: 3 | D20: 3
A21: DENMARK | B21: 1 | C21: 2 | D21: 3
A22: ECUADOR | C22: 1 | D22: 1
A23: EGYPT | C23: 1 | D23: 1
A24: ENGLAND | B24: 4 | C24: 14 | D24: 18
A25: FRANCE | B25: 4 | C25: 18 | D25: 22
A26: GEORGIA | C26: 1 | D26: 1
A27: GERMANY | B27: 1 | C27: 15 | D27: 16
A28: HUNGARY | C28: 1 | D28: 1
A29: IRELAND | C29: 1 | D29: 1
A30: ITALY | C30: 15 | D30: 15
A31: IVORY-COAST | C31: 2 | D31: 2
A32: JAPAN | B32: 1 | D32: 1
A33: MEXICO | C33: 1 | D33: 1
A34: MOROCCO | C34: 2 | D34: 2
A35: NETHERLANDS | B35: 2 | C35: 8 | D35: 10
A36: NIGERIA | B36: 1 | C36: 1 | D36: 2
A37: NORWAY | B37: 1 | C37: 1 | D37: 2
A38: NULL | C38: 31 | D38: 31
A39: POLAND | C39: 2 | D39: 2
A40: PORTUGAL | C40: 9 | D40: 9
A41: RUSSIA | C41: 1 | D41: 1
A42: SCOTLAND | C42: 1 | D42: 1
...

Sheet EclaterColonne
A1: Name | B1: Name1 | C1: Name2 | J1: Name
A2: Alex Morgan | B2: Alex | C2: Morgan | J2: Alex | K2: Morgan | L2: =PROPER(J2) -> Alex | M2: =UPPER(K2) -> MORGAN
A3: Megan Rapinoe | B3: Megan | C3: Rapinoe | J3: Megan | K3: Rapinoe | L3: =PROPER(J3) -> Megan | M3: =UPPER(K3) -> RAPINOE
A4: Sam Kerr | B4: Sam | C4: Kerr | J4: Sam | K4: Kerr | L4: =PROPER(J4) -> Sam | M4: =UPPER(K4) -> KERR
A5: Lucy Bronze | B5: Lucy | C5: Bronze | J5: Lucy | K5: Bronze | L5: =PROPER(J5) -> Lucy | M5: =UPPER(K5) -> BRONZE
A6: Amandine Henry | B6: Amandine | C6: Henry | J6: Amandine | K6: Henry | L6: =PROPER(J6) -> Amandine | M6: =UPPER(K6) -> HENRY
A7: Marta Vieira da Silva | B7: Marta | C7: Vieira | D7: da | E7: Silva | J7: Marta | K7: Vieira-da-Silva | L7: =PROPER(J7) -> Marta | M7: =UPPER(K7) -> VIEIRA-DA-SILVA
A8: Christine Sinclair | B8: Christine | C8: Sinclair | J8: Christine | K8: Sinclair | L8: =PROPER(J8) -> Christine | M8: =UPPER(K8) -> SINCLAIR
A9: Vivianne Miedema | B9: Vivianne | C9: Miedema | J9: Vivianne | K9: Miedema | L9: =PROPER(J9) -> Vivianne | M9: =UPPER(K9) -> MIEDEMA
A10: Fran Kirby | B10: Fran | C10: Kirby | J10: Fran | K10: Kirby | L10: =PROPER(J10) -> Fran | M10: =UPPER(K10) -> KIRBY
A11: Ada Hegerberg | B11: Ada | C11: Hegerberg | J11: Ada | K11: Hegerberg | L11: =PROPER(J11) -> Ada | M11: =UPPER(K11) -> HEGERBERG
A12: Dzsenifer Marozsán | B12: Dzsenifer | C12: Marozsán | J12: Dzsenifer | K12: Marozsán | L12: =PROPER(J12) -> Dzsenifer | M12: =UPPER(K12) -> MAROZSÁN
A13: Wendie Renard | B13: Wendie | C13: Renard | J13: Wendie | K13: Renard | L13: =PROPER(J13) -> Wendie | M13: =UPPER(K13) -> RENARD
A14: Julie Ertz | B14: Julie | C14: Ertz | J14: Julie | K14: Ertz | L14: =PROPER(J14) -> Julie | M14: =UPPER(K14) -> ERTZ
A15: Carli Lloyd | B15: Carli | C15: Lloyd | J15: Carli | K15: Lloyd | L15: =PROPER(J15) -> Carli | M15: =UPPER(K15) -> LLOYD
A16: Tobin Heath | B16: Tobin | C16: Heath | J16: Tobin | K16: Heath | L16: =PROPER(J16) -> Tobin | M16: =UPPER(K16) -> HEATH
A17: Rose Lavelle | B17: Rose | C17: Lavelle | J17: Rose | K17: Lavelle | L17: =PROPER(J17) -> Rose | M17: =UPPER(K17) -> LAVELLE
A18: Pernille Harder | B18: Pernille | C18: Harder | J18: Pernille | K18: Harder | L18: =PROPER(J18) -> Pernille | M18: =UPPER(K18) -> HARDER
A19: Lieke Martens | B19: Lieke | C19: Martens | J19: Lieke | K19: Martens | L19: =PROPER(J19) -> Lieke | M19: =UPPER(K19) -> MARTENS
... A31: Leah Williamson | B31: Leah | C31: Williamson | J31: Leah | K31: Williamson | L31: =PROPER(J31) -> Leah | M31: =UPPER(K31) -> WILLIAMSON

Sheet Tab1_Joueurs
A1: ID | B1: NOM | C1: Prénom | D1: Poste | E1: Pays d'origine | F1: Année2Naissance | J1: ID Colonne | K1: Col0 | L1: Col1 | M1: Col2 | N1: Col3 | O1: Col4 | P1: Col5 | Q1: Col6 | S1: ', ' | T1: =MAX(T2:T157) -> 10 | U1: =MAX(U2:U157) -> 16 | V1: =MAX(V2:V157) -> 11 | W1: =MAX(W2:W157) -> 9 | X1: =MAX(X2:X157) -> 14 | Y1: =MAX(Y2:Y157) -> 4 | Z1: Min
A2: 1991AlgMah | B2: Mahrez | C2: Riyad | D2: Milieu | E2: Algérie | F2: 1991 | J2: Nom Colonne | K2: Source | L2: ID | M2: NOM | N2: Prénom | O2: Poste | P2: Pays d'origine | Q2: Année2Naissance | T2: =LEN(A2) -> 10 | U2: =LEN(B2) -> 6 | V2: =LEN(C2) -> 5 | W2: =LEN(D2) -> 6 | X2: =LEN(E2) -> 7 | Y2: =LEN(F2) -> 4 | Z2: =MIN($F$2:$F$157) -> 1978
A3: 1986AllNeu | B3: Neuer | C3: Manuel | D3: Gardien | E3: Allemagne | F3: 1986 | J3: Type Colonne | K3: Tab1_Joueurs | L3: String | M3: String | N3: String | O3: String | P3: String | Q3: Number | S3: =CONCATENATE("INSERT INTO Tab1_Joueurs VALUES ('",A2,$S$1,B2,$S$1,C2,$S$1,D2,$S$1,E2,$S$1,F2,"');") -> INSERT INTO Tab1_Joueurs VALUES ('1991AlgMah', 'Mahrez', 'Riyad', 'Milieu', 'Algérie', '1991'); | T3: =LEN(A3) -> 10 | U3: =LEN(B3) -> 5 | V3: =LEN(C3) -> 6 | W3: =LEN(D3) -> 7 | X3: =LEN(E3) -> 9 | Y3: =LEN(F3) -> 4 | Z3: Max
A4: 1989AllMül | B4: Müller | C4: Thomas | D4: Milieu | E4: Allemagne | F4: 1989 | J4: Longueur Colonne | K4: Tab1_Joueurs | L4: 10 | M4: 16 | N4: 11 | O4: 9 | P4: 14 | Q4: 4 | S4: =CONCATENATE("INSERT INTO Tab1_Joueurs VALUES ('",A3,$S$1,B3,$S$1,C3,$S$1,D3,$S$1,E3,$S$1,F3,"');") -> INSERT INTO Tab1_Joueurs VALUES ('1986AllNeu', 'Neuer', 'Manuel', 'Gardien', 'Allemagne', '1986'); | T4: =LEN(A4) -> 10 | U4: =LEN(B4) -> 6 | V4: =LEN(C4) -> 6 | W4: =LEN(D4) -> 6 | X4: =LEN(E4) -> 9 | Y4: =LEN(F4) -> 4 | Z4: =MAX($F$2:$F$157) -> 2008
A5: 1989AllÖzi | B5: Özil | C5: Mesut | D5: Milieu | E5: Allemagne | F5: 1989 | J5: Format Colonne | K5: Tab1_Joueurs | L5: NNNNCCCC | M5: INITCAP | N5: INITCAP | O5: INITCAP | P5: INITCAP | Q5: YYYY | S5: =CONCATENATE("INSERT INTO Tab1_Joueurs VALUES ('",A4,$S$1,B4,$S$1,C4,$S$1,D4,$S$1,E4,$S$1,F4,"');") -> INSERT INTO Tab1_Joueurs VALUES ('1989AllMül', 'Müller', 'Thomas', 'Milieu', 'Allemagne', '1989'); | T5: =LEN(A5) -> 10 | U5: =LEN(B5) -> 4 | V5: =LEN(C5) -> 5 | W5: =LEN(D5) -> 6 | X5: =LEN(E5) -> 9 | Y5: =LEN(F5) -> 4 | Z5: Moy
A6: 1989AllReu | B6: Reus | C6: Marco | D6: Attaquant | E6: Allemagne | F6: 1989 | J6: Langue Colonne | K6: Tab1_Joueurs | M6: Français ?? | N6: Français ?? | O6: Français | P6: Français | S6: =CONCATENATE("INSERT INTO Tab1_Joueurs VALUES ('",A5,$S$1,B5,$S$1,C5,$S$1,D5,$S$1,E5,$S$1,F5,"');") -> INSERT INTO Tab1_Joueurs VALUES ('1989AllÖzi', 'Özil', 'Mesut', 'Milieu', 'Allemagne', '1989'); | T6: =LEN(A6) -> 10 | U6: =LEN(B6) -> 4 | V6: =LEN(C6) -> 5 | W6: =LEN(D6) -> 9 | X6: =LEN(E6) -> 9 | Y6: =LEN(F6) -> 4 | Z6: =AVERAGE($F$2:$F$157) -> 1995.4872
A7: 1990AllKro | B7: Kroos | C7: Toni | D7: Milieu | E7: Allemagne | F7: 1990 | J7: Valeurs Uniques | K7: Tab1_Joueurs | L7: Oui | M7: Non | N7: Non | O7: Non | P7: Non | Q7: Non | S7: =CONCATENATE("INSERT INTO Tab1_Joueurs VALUES ('",A6,$S$1,B6,$S$1,C6,$S$1,D6,$S$1,E6,$S$1,F6,"');") -> INSERT INTO Tab1_Joueurs VALUES ('1989AllReu', 'Reus', 'Marco', 'Attaquant', 'Allemagne', '1989'); | T7: =LEN(A7) -> 10 | U7: =LEN(B7) -> 5 | V7: =LEN(C7) -> 4 | W7: =LEN(D7) -> 6 | X7: =LEN(E7) -> 9 | Y7: =LEN(F7) -> 4
A8: 1991AllGün | B8: Gündoğan | C8: Ilkay | D8: Milieu | E8: Allemagne | F8: 1991 | J8: Nombre de Valeurs Présentes | K8: Tab1_Joueurs | L8: 156 | M8: 156 | N8: 156 | O8: 156 | P8: 156 | Q8: 156 | S8: =CONCATENATE("INSERT INTO Tab1_Joueurs VALUES ('",A7,$S$1,B7,$S$1,C7,$S$1,D7,$S$1,E7,$S$1,F7,"');") -> INSERT INTO Tab1_Joueurs VALUES ('1990AllKro', 'Kroos', 'Toni', 'Milieu', 'Allemagne', '1990'); | T8: =LEN(A8) -> 10 | U8: =LEN(B8) -> 8 | V8: =LEN(C8) -> 5 | W8: =LEN(D8) -> 6 | X8: =LEN(E8) -> 9 | Y8: =LEN(F8) -> 4 | Z8: Nbval | AA8: =COUNTA(A$2:A$157) -> 156 | AB8: =COUNTA(B$2:B$157) -> 156 | AC8: =COUNTA(C$2:C$157) -> 156 | AD8: =COUNTA(D$2:D$157) -> 156 | AE8: =COUNTA(E$2:E$157) -> 156 | AF8: =COUNTA(F$2:F$157) -> 156
A9: 1993AllTer | B9: Ter Stegen | C9: Marc-André | D9: Gardien | E9: Allemagne | F9: 1993 | J9: Nombre de Valeurs Manquantes | K9: Tab1_Joueurs | L9: 0 | M9: 0 | N9: 0 | O9: 0 | P9: 0 | Q9: 0 | S9: =CONCATENATE("INSERT INTO Tab1_Joueurs VALUES ('",A8,$S$1,B8,$S$1,C8,$S$1,D8,$S$1,E8,$S$1,F8,"');") -> INSERT INTO Tab1_Joueurs VALUES ('1991AllGün', 'Gündoğan', 'Ilkay', 'Milieu', 'Allemagne', '1991'); | T9: =LEN(A9) -> 10 | U9: =LEN(B9) -> 10 | V9: =LEN(C9) -> 10 | W9: =LEN(D9) -> 7 | X9: =LEN(E9) -> 9 | Y9: =LEN(F9) -> 4
A10: 1995AllKim | B10: Kimmich | C10: Joshua | D10: Milieu | E10: Allemagne | F10: 1995 | J10: Nombre de valeurs en UPPER uniquement | K10: Tab1_Joueurs | L10: 0 | M10: 0 | N10: 0 | O10: 0 | P10: 0 | Q10: 0 | S10: =CONCATENATE("INSERT INTO Tab1_Joueurs VALUES ('",A9,$S$1,B9,$S$1,C9,$S$1,D9,$S$1,E9,$S$1,F9,"');") -> INSERT INTO Tab1_Joueurs VALUES ('1993AllTer', 'Ter Stegen', 'Marc-André', 'Gardien', 'Allemagne', '1993'); | T10: =LEN(A10) -> 10 | U10: =LEN(B10) -> 7 | V10: =LEN(C10) -> 6 | W10: =LEN(D10) -> 6 | X10: =LEN(E10) -> 9 | Y10: =LEN(F10) -> 4
A11: 1996AllSan | B11: Sané | C11: Leroy | D11: Attaquant | E11: Allemagne | F11: 1996 | J11: Nombre de valeurs en LOWER uniquement | K11: Tab1_Joueurs | L11: 0 | M11: 0 | N11: 0 | O11: 0 | P11: 0 | Q11: 0 | S11: =CONCATENATE("INSERT INTO Tab1_Joueurs VALUES ('",A10,$S$1,B10,$S$1,C10,$S$1,D10,$S$1,E10,$S$1,F10,"');") -> INSERT INTO Tab1_Joueurs VALUES ('1995AllKim', 'Kimmich', 'Joshua', 'Milieu', 'Allemagne', '1995'); | T11: =LEN(A11) -> 10 | U11: =LEN(B11) -> 4 | V11: =LEN(C11) -> 5 | W11: =LEN(D11) -> 9 | X11: =LEN(E11) -> 9 | Y11: =LEN(F11) -> 4
A12: 1997AllGna | B12: Gnabry | C12: Serge | D12: Attaquant | E12: Allemagne | F12: 1997 | J12: Nombre de valeurs en INITCAP uniquement | K12: Tab1_Joueurs | L12: 156 | M12: 156 | N12: 156 | O12: 156 | P12: 156 | Q12: 0 | S12: =CONCATENATE("INSERT INTO Tab1_Joueurs VALUES ('",A11,$S$1,B11,$S$1,C11,$S$1,D11,$S$1,E11,$S$1,F11,"');") -> INSERT INTO Tab1_Joueurs VALUES ('1996AllSan', 'Sané', 'Leroy', 'Attaquant', 'Allemagne', '1996'); | T12: =LEN(A12) -> 10 | U12: =LEN(B12) -> 6 | V12: =LEN(C12) -> 5 | W12: =LEN(D12) -> 9 | X12: =LEN(E12) -> 9 | Y12: =LEN(F12) -> 4
A13: 2003AllWir | B13: Wirtz | C13: Florian | D13: Milieu | E13: Allemagne | F13: 2003 | J13: Nombre de valeurs en MIXTE | K13: Tab1_Joueurs | L13: 0 | M13: 0 | N13: 0 | O13: 0 | P13: 0 | Q13: 0 | S13: =CONCATENATE("INSERT INTO Tab1_Joueurs VALUES ('",A12,$S$1,B12,$S$1,C12,$S$1,D12,$S$1,E12,$S$1,F12,"');") -> INSERT INTO Tab1_Joueurs VALUES ('1997AllGna', 'Gnabry', 'Serge', 'Attaquant', 'Allemagne', '1997'); | T13: =LEN(A13) -> 10 | U13: =LEN(B13) -> 5 | V13: =LEN(C13) -> 7 | W13: =LEN(D13) -> 6 | X13: =LEN(E13) -> 9 | Y13: =LEN(F13) -> 4
A14: 2004AllMus | B14: Musiala | C14: Jamal | D14: Milieu | E14: Allemagne | F14: 2004 | J14: REGEX Colonne | K14: Tab1_Joueurs | L14: ^[A..Za..z] ?-.öè | M14: ^[A..Za..z] ?-.öè | N14: ^[A..Za..z] ?-.öè | O14: ^[A..Za..z] ?-.öè | P14: ^[A..Za..z] ?-.öè | Q14: 1920<Y<2050 | S14: =CONCATENATE("INSERT INTO Tab1_Joueurs VALUES ('",A13,$S$1,B13,$S$1,C13,$S$1,D13,$S$1,E13,$S$1,F13,"');") -> INSERT INTO Tab1_Joueurs VALUES ('2003AllWir', 'Wirtz', 'Florian', 'Milieu', 'Allemagne', '2003'); | T14: =LEN(A14) -> 10 | U14: =LEN(B14) -> 7 | V14: =LEN(C14) -> 5 | W14: =LEN(D14) -> 6 | X14: =LEN(E14) -> 9 | Y14: =LEN(F14) -> 4
A15: 2005AllMou | B15: Moukoko | C15: Youssoufa | D15: Attaquant | E15: Allemagne | F15: 2005 | J15: Nombre de valeurs avec ESPACE | K15: Tab1_Joueurs | Q15: 0 | S15: =CONCATENATE("INSERT INTO Tab1_Joueurs VALUES ('",A14,$S$1,B14,$S$1,C14,$S$1,D14,$S$1,E14,$S$1,F14,"');") -> INSERT INTO Tab1_Joueurs VALUES ('2004AllMus', 'Musiala', 'Jamal', 'Milieu', 'Allemagne', '2004'); | T15: =LEN(A15) -> 10 | U15: =LEN(B15) -> 7 | V15: =LEN(C15) -> 9 | W15: =LEN(D15) -> 9 | X15: =LEN(E15) -> 9 | Y15: =LEN(F15) -> 4
A16: 1978AngLam | B16: Lampard | C16: Frank | D16: Milieu | E16: Angleterre | F16: 1978 | J16: Nombre de valeurs avec TIRET | K16: Tab1_Joueurs | Q16: 0 | S16: =CONCATENATE("INSERT INTO Tab1_Joueurs VALUES ('",A15,$S$1,B15,$S$1,C15,$S$1,D15,$S$1,E15,$S$1,F15,"');") -> INSERT INTO Tab1_Joueurs VALUES ('2005AllMou', 'Moukoko', 'Youssoufa', 'Attaquant', 'Allemagne', '2005'); | T16: =LEN(A16) -> 10 | U16: =LEN(B16) -> 7 | V16: =LEN(C16) -> 5 | W16: =LEN(D16) -> 6 | X16: =LEN(E16) -> 10 | Y16: =LEN(F16) -> 4
A17: 1980AngGer | B17: Gerrard | C17: Steven | D17: Milieu | E17: Angleterre | F17: 1980 | J17: Nombre de valeurs avec APOSTROPHE | K17: Tab1_Joueurs | Q17: 0 | S17: =CONCATENATE("INSERT INTO Tab1_Joueurs VALUES ('",A16,$S$1,B16,$S$1,C16,$S$1,D16,$S$1,E16,$S$1,F16,"');") -> INSERT INTO Tab1_Joueurs VALUES ('1978AngLam', 'Lampard', 'Frank', 'Milieu', 'Angleterre', '1978'); | T17: =LEN(A17) -> 10 | U17: =LEN(B17) -> 7 | V17: =LEN(C17) -> 6 | W17: =LEN(D17) -> 6 | X17: =LEN(E17) -> 10 | Y17: =LEN(F17) -> 4
A18: 1992AngPop | B18: Pope | C18: Nick | D18: Gardien | E18: Angleterre | F18: 1992 | J18: Nombre de valeurs INCORRECTES | K18: Tab1_Joueurs | Q18: 0 | S18: =CONCATENATE("INSERT INTO Tab1_Joueurs VALUES ('",A17,$S$1,B17,$S$1,C17,$S$1,D17,$S$1,E17,$S$1,F17,"');") -> INSERT INTO Tab1_Joueurs VALUES ('1980AngGer', 'Gerrard', 'Steven', 'Milieu', 'Angleterre', '1980'); | T18: =LEN(A18) -> 10 | U18: =LEN(B18) -> 4 | V18: =LEN(C18) -> 4 | W18: =LEN(D18) -> 7 | X18: =LEN(E18) -> 10 | Y18: =LEN(F18) -> 4
A19: 1993AngKan | B19: Kane | C19: Harry | D19: Attaquant | E19: Angleterre | F19: 1993 | J19: Nombre de valeurs CORRECTES | K19: Tab1_Joueurs | Q19: 0 | S19: =CONCATENATE("INSERT INTO Tab1_Joueurs VALUES ('",A18,$S$1,B18,$S$1,C18,$S$1,D18,$S$1,E18,$S$1,F18,"');") -> INSERT INTO Tab1_Joueurs VALUES ('1992AngPop', 'Pope', 'Nick', 'Gardien', 'Angleterre', '1992'); | T19: =LEN(A19) -> 10 | U19: =LEN(B19) -> 4 | V19: =LEN(C19) -> 5 | W19: =LEN(D19) -> 9 | X19: =LEN(E19) -> 10 | Y19: =LEN(F19) -> 4
A20: 1994AngPic | B20: Pickford | C20: Jordan | D20: Gardien | E20: Angleterre | F20: 1994 | J20: Nombre de doublons exacts | K20: Tab1_Joueurs | S20: =CONCATENATE("INSERT INTO Tab1_Joueurs VALUES ('",A19,$S$1,B19,$S$1,C19,$S$1,D19,$S$1,E19,$S$1,F19,"');") -> INSERT INTO Tab1_Joueurs VALUES ('1993AngKan', 'Kane', 'Harry', 'Attaquant', 'Angleterre', '1993'); | T20: =LEN(A20) -> 10 | U20: =LEN(B20) -> 8 | V20: =LEN(C20) -> 6 | W20: =LEN(D20) -> 7 | X20: =LEN(E20) -> 10 | Y20: =LEN(F20) -> 4
A21: 1995AngSte | B21: Sterling | C21: Raheem | D21: Attaquant | E21: Angleterre | F21: 1995 | J21: Min Colonne | K21: Tab1_Joueurs | Q21: 1978 | S21: =CONCATENATE("INSERT INTO Tab1_Joueurs VALUES ('",A20,$S$1,B20,$S$1,C20,$S$1,D20,$S$1,E20,$S$1,F20,"');") -> INSERT INTO Tab1_Joueurs VALUES ('1994AngPic', 'Pickford', 'Jordan', 'Gardien', 'Angleterre', '1994'); | T21: =LEN(A21) -> 10 | U21: =LEN(B21) -> 8 | V21: =LEN(C21) -> 6 | W21: =LEN(D21) -> 9 | X21: =LEN(E21) -> 10 | Y21: =LEN(F21) -> 4
A22: 1997AngRas | B22: Rashford | C22: Marcus | D22: Attaquant | E22: Angleterre | F22: 1997 | J22: Max Colonne | K22: Tab1_Joueurs | Q22: 2008 | S22: =CONCATENATE("INSERT INTO Tab1_Joueurs VALUES ('",A21,$S$1,B21,$S$1,C21,$S$1,D21,$S$1,E21,$S$1,F21,"');") -> INSERT INTO Tab1_Joueurs VALUES ('1995AngSte', 'Sterling', 'Raheem', 'Attaquant', 'Angleterre', '1995'); | T22: =LEN(A22) -> 10 | U22: =LEN(B22) -> 8 | V22: =LEN(C22) -> 6 | W22: =LEN(D22) -> 9 | X22: =LEN(E22) -> 10 | Y22: =LEN(F22) -> 4
A23: 1999AngAle | B23: Alexander-Arnold | C23: Trent | D23: Défenseur | E23: Angleterre | F23: 1999 | J23: Moy Colonne | K23: Tab1_Joueurs | Q23: 1995.4872 | S23: =CONCATENATE("INSERT INTO Tab1_Joueurs VALUES ('",A22,$S$1,B22,$S$1,C22,$S$1,D22,$S$1,E22,$S$1,F22,"');") -> INSERT INTO Tab1_Joueurs VALUES ('1997AngRas', 'Rashford', 'Marcus', 'Attaquant', 'Angleterre', '1997'); | T23: =LEN(A23) -> 10 | U23: =LEN(B23) -> 16 | V23: =LEN(C23) -> 5 | W23: =LEN(D23) -> 9 | X23: =LEN(E23) -> 10 | Y23: =LEN(F23) -> 4
A24: 1999AngRam | B24: Ramsdale | C24: Aaron | D24: Gardien | E24: Angleterre | F24: 1999 | K24: Tab1_Joueurs_001 | L24: 1991AlgMah | M24: Mahrez | N24: Riyad | O24: Milieu | P24: Algérie | Q24: 1991 | S24: =CONCATENATE("INSERT INTO Tab1_Joueurs VALUES ('",A23,$S$1,B23,$S$1,C23,$S$1,D23,$S$1,E23,$S$1,F23,"');") -> INSERT INTO Tab1_Joueurs VALUES ('1999AngAle', 'Alexander-Arnold', 'Trent', 'Défenseur', 'Angleterre', '1999'); | T24: =LEN(A24) -> 10 | U24: =LEN(B24) -> 8 | V24: =LEN(C24) -> 5 | W24: =LEN(D24) -> 7 | X24: =LEN(E24) -> 10 | Y24: =LEN(F24) -> 4
A25: 2000AngFod | B25: Foden | C25: Phil | D25: Milieu | E25: Angleterre | F25: 2000 | K25: Tab1_Joueurs_002 | L25: 1986AllNeu | M25: Neuer | N25: Manuel | O25: Gardien | P25: Allemagne | Q25: 1986 | S25: =CONCATENATE("INSERT INTO Tab1_Joueurs VALUES ('",A24,$S$1,B24,$S$1,C24,$S$1,D24,$S$1,E24,$S$1,F24,"');") -> INSERT INTO Tab1_Joueurs VALUES ('1999AngRam', 'Ramsdale', 'Aaron', 'Gardien', 'Angleterre', '1999'); | T25: =LEN(A25) -> 10 | U25: =LEN(B25) -> 5 | V25: =LEN(C25) -> 4 | W25: =LEN(D25) -> 6 | X25: =LEN(E25) -> 10 | Y25: =LEN(F25) -> 4
A26: 2000AngMou | B26: Mount | C26: Mason | D26: Milieu | E26: Angleterre | F26: 2000 | K26: Tab1_Joueurs_003 | L26: 1989AllMül | M26: Müller | N26: Thomas | O26: Milieu | P26: Allemagne | Q26: 1989 | S26: =CONCATENATE("INSERT INTO Tab1_Joueurs VALUES ('",A25,$S$1,B25,$S$1,C25,$S$1,D25,$S$1,E25,$S$1,F25,"');") -> INSERT INTO Tab1_Joueurs VALUES ('2000AngFod', 'Foden', 'Phil', 'Milieu', 'Angleterre', '2000'); | T26: =LEN(A26) -> 10 | U26: =LEN(B26) -> 5 | V26: =LEN(C26) -> 5 | W26: =LEN(D26) -> 6 | X26: =LEN(E26) -> 10 | Y26: =LEN(F26) -> 4
A27: 2003AngBel | B27: Bellingham | C27: Jude | D27: Milieu | E27: Angleterre | F27: 2003 | K27: Tab1_Joueurs_004 | L27: 1989AllÖzi | M27: Özil | N27: Mesut | O27: Milieu | P27: Allemagne | Q27: 1989 | S27: =CONCATENATE("INSERT INTO Tab1_Joueurs VALUES ('",A26,$S$1,B26,$S$1,C26,$S$1,D26,$S$1,E26,$S$1,F26,"');") -> INSERT INTO Tab1_Joueurs VALUES ('2000AngMou', 'Mount', 'Mason', 'Milieu', 'Angleterre', '2000'); | T27: =LEN(A27) -> 10 | U27: =LEN(B27) -> 10 | V27: =LEN(C27) -> 4 | W27: =LEN(D27) -> 6 | X27: =LEN(E27) -> 10 | Y27: =LEN(F27) -> 4
A28: 2004AngChu | B28: Chukwuemeka | C28: Carney | D28: Milieu | E28: Angleterre | F28: 2004 | K28: Tab1_Joueurs_005 | L28: 1989AllReu | M28: Reus | N28: Marco | O28: Attaquant | P28: Allemagne | Q28: 1989 | S28: =CONCATENATE("INSERT INTO Tab1_Joueurs VALUES ('",A27,$S$1,B27,$S$1,C27,$S$1,D27,$S$1,E27,$S$1,F27,"');") -> INSERT INTO Tab1_Joueurs VALUES ('2003AngBel', 'Bellingham', 'Jude', 'Milieu', 'Angleterre', '2003'); | T28: =LEN(A28) -> 10 | U28: =LEN(B28) -> 11 | V28: =LEN(C28) -> 6 | W28: =LEN(D28) -> 6 | X28: =LEN(E28) -> 10 | Y28: =LEN(F28) -> 4
A29: 1987ArgMes | B29: Messi | C29: Lionel | D29: Attaquant | E29: Argentine | F29: 1987 | K29: Tab1_Joueurs_006 | L29: 1990AllKro | M29: Kroos | N29: Toni | O29: Milieu | P29: Allemagne | Q29: 1990 | S29: =CONCATENATE("INSERT INTO Tab1_Joueurs VALUES ('",A28,$S$1,B28,$S$1,C28,$S$1,D28,$S$1,E28,$S$1,F28,"');") -> INSERT INTO Tab1_Joueurs VALUES ('2004AngChu', 'Chukwuemeka', 'Carney', 'Milieu', 'Angleterre', '2004'); | T29: =LEN(A29) -> 10 | U29: =LEN(B29) -> 5 | V29: =LEN(C29) -> 6 | W29: =LEN(D29) -> 9 | X29: =LEN(E29) -> 9 | Y29: =LEN(F29) -> 4
A30: 1988ArgDi | B30: Di Maria | C30: Ãngel | D30: Milieu | E30: Argentine | F30: 1988 | K30: Tab1_Joueurs_007 | L30: 1991AllGün | M30: Gündoğan | N30: Ilkay | O30: Milieu | P30: Allemagne | Q30: 1991 | S30: =CONCATENATE("INSERT INTO Tab1_Joueurs VALUES ('",A29,$S$1,B29,$S$1,C29,$S$1,D29,$S$1,E29,$S$1,F29,"');") -> INSERT INTO Tab1_Joueurs VALUES ('1987ArgMes', 'Messi', 'Lionel', 'Attaquant', 'Argentine', '1987'); | T30: =LEN(A30) -> 10 | U30: =LEN(B30) -> 8 | V30: =LEN(C30) -> 6 | W30: =LEN(D30) -> 6 | X30: =LEN(E30) -> 9 | Y30: =LEN(F30) -> 4
A31: 1993ArgMar | B31: Martínez | C31: Emiliano | D31: Gardien | E31: Argentine | F31: 1993 | K31: Tab1_Joueurs_008 | L31: 1993AllTer | M31: Ter Stegen | N31: Marc-André | O31: Gardien | P31: Allemagne | Q31: 1993 | S31: =CONCATENATE("INSERT INTO Tab1_Joueurs VALUES ('",A30,$S$1,B30,$S$1,C30,$S$1,D30,$S$1,E30,$S$1,F30,"');") -> INSERT INTO Tab1_Joueurs VALUES ('1988ArgDi ', 'Di Maria', 'Ãngel', 'Milieu', 'Argentine', '1988'); | T31: =LEN(A31) -> 10 | U31: =LEN(B31) -> 8 | V31: =LEN(C31) -> 8 | W31: =LEN(D31) -> 7 | X31: =LEN(E31) -> 9 | Y31: =LEN(F31) -> 4
A32: 1994ArgDyb | B32: Dybala | C32: Paulo | D32: Attaquant | E32: Argentine | F32: 1994 | K32: Tab1_Joueurs_009 | L32: 1995AllKim | M32: Kimmich | N32: Joshua | O32: Milieu | P32: Allemagne | Q32: 1995 | S32: =CONCATENATE("INSERT INTO Tab1_Joueurs VALUES ('",A31,$S$1,B31,$S$1,C31,$S$1,D31,$S$1,E31,$S$1,F31,"');") -> INSERT INTO Tab1_Joueurs VALUES ('1993ArgMar', 'Martínez', 'Emiliano', 'Gardien', 'Argentine', '1993'); | T32: =LEN(A32) -> 10 | U32: =LEN(B32) -> 6 | V32: =LEN(C32) -> 5 | W32: =LEN(D32) -> 9 | X32: =LEN(E32) -> 9 | Y32: =LEN(F32) -> 4
A33: 1998ArgLau | B33: Lautaro | C33: Martínez | D33: Attaquant | E33: Argentine | F33: 1998 | K33: Tab1_Joueurs_010 | L33: 1996AllSan | M33: Sané | N33: Leroy | O33: Attaquant | P33: Allemagne | Q33: 1996 | S33: =CONCATENATE("INSERT INTO Tab1_Joueurs VALUES ('",A32,$S$1,B32,$S$1,C32,$S$1,D32,$S$1,E32,$S$1,F32,"');") -> INSERT INTO Tab1_Joueurs VALUES ('1994ArgDyb', 'Dybala', 'Paulo', 'Attaquant', 'Argentine', '1994'); | T33: =LEN(A33) -> 10 | U33: =LEN(B33) -> 7 | V33: =LEN(C33) -> 8 | W33: =LEN(D33) -> 9 | X33: =LEN(E33) -> 9 | Y33: =LEN(F33) -> 4
A34: 1998ArgMar | B34: Martínez | C34: Lautaro | D34: Attaquant | E34: Argentine | F34: 1998 | K34: Tab1_Joueurs_011 | L34: 1997AllGna | M34: Gnabry | N34: Serge | O34: Attaquant | P34: Allemagne | Q34: 1997 | S34: =CONCATENATE("INSERT INTO Tab1_Joueurs VALUES ('",A33,$S$1,B33,$S$1,C33,$S$1,D33,$S$1,E33,$S$1,F33,"');") -> INSERT INTO Tab1_Joueurs VALUES ('1998ArgLau', 'Lautaro', 'Martínez', 'Attaquant', 'Argentine', '1998'); | T34: =LEN(A34) -> 10 | U34: =LEN(B34) -> 8 | V34: =LEN(C34) -> 7 | W34: =LEN(D34) -> 9 | X34: =LEN(E34) -> 9 | Y34: =LEN(F34) -> 4
A35: 2002ArgAlm | B35: Almada | C35: Thiago | D35: Milieu | E35: Argentine | F35: 2002 | K35: Tab1_Joueurs_012 | L35: 2003AllWir | M35: Wirtz | N35: Florian | O35: Milieu | P35: Allemagne | Q35: 2003 | S35: =CONCATENATE("INSERT INTO Tab1_Joueurs VALUES ('",A34,$S$1,B34,$S$1,C34,$S$1,D34,$S$1,E34,$S$1,F34,"');") -> INSERT INTO Tab1_Joueurs VALUES ('1998ArgMar', 'Martínez', 'Lautaro', 'Attaquant', 'Argentine', '1998'); | T35: =LEN(A35) -> 10 | U35: =LEN(B35) -> 6 | V35: =LEN(C35) -> 6 | W35: =LEN(D35) -> 6 | X35: =LEN(E35) -> 9 | Y35: =LEN(F35) -> 4
... A157: 2002UruUga | B157: Ugarte | C157: Manuel | D157: Milieu | E157: Uruguay | F157: 2002 | K157: Tab1_Joueurs_134 | L157: 1991PolSzc | M157: Szczęsny | N157: Wojciech | O157: Gardien | P157: Pologne | Q157: 1991 | S157: =CONCATENATE("INSERT INTO Tab1_Joueurs VALUES ('",A156,$S$1,B156,$S$1,C156,$S$1,D156,$S$1,E156,$S$1,F156,"');") -> INSERT INTO Tab1_Joueurs VALUES ('1998UruVal', 'Valverde', 'Federico', 'Milieu', 'Uruguay', '1998'); | T157: =LEN(A157) -> 10 | U157: =LEN(B157) -> 6 | V157: =LEN(C157) -> 6 | W157: =LEN(D157) -> 6 | X157: =LEN(E157) -> 7 | Y157: =LEN(F157) -> 4
K158: Tab1_Joueurs_135 | L158: 1985PorRon | M158: Ronaldo | N158: Cristiano | O158: Attaquant | P158: Portugal | Q158: 1985 | S158: =CONCATENATE("INSERT INTO Tab1_Joueurs VALUES ('",A157,$S$1,B157,$S$1,C157,$S$1,D157,$S$1,E157,$S$1,F157,"');") -> INSERT INTO Tab1_Joueurs VALUES ('2002UruUga', 'Ugarte', 'Manuel', 'Milieu', 'Uruguay', '2002');
K159: Tab1_Joueurs_136 | L159: 1994PorBer | M159: Bernardo | N159: Silva | O159: Milieu | P159: Portugal | Q159: 1994
K160: Tab1_Joueurs_137 | L160: 1995PorFer | M160: Fernandes | N160: Bruno | O160: Milieu | P160: Portugal | Q160: 1995
K161: Tab1_Joueurs_138 | L161: 1997PorDia | M161: Dias | N161: Rúben | O161: Défenseur | P161: Portugal | Q161: 1997
...

Sheet Tab2_Goalkeeper
A1: ID | B1: FirstName | C1: LastName | D1: Position | E1: Country_Origin | J1: ID Colonne | K1: Col0 | L1: Col1 | M1: Col2 | N1: Col3 | O1: Col4 | P1: Col5 | S1: ', ' | T1: =MAX(T2:T157) -> 7 | U1: =MAX(U2:U157) -> 10 | V1: =MAX(V2:V157) -> 10 | W1: =MAX(W2:W157) -> 10 | X1: =MAX(X2:X157) -> 11 | Y1: =MAX(Y2:Y157) -> #REF! | Z1: Min
A2: GERGK01 | B2: Manuel | C2: NEUER | D2: Goalkeeper | E2: GERMANY | J2: Nom Colonne | K2: Source | L2: ID | M2: FirstName | N2: LastName | O2: Position | P2: Country_Origin | S2: =CONCATENATE("INSERT INTO Tab2_Goalkeeper VALUES ('",A2,$S$1,B2,$S$1,C2,$S$1,D2,$S$1,E2,"');") -> INSERT INTO Tab2_Goalkeeper VALUES ('GERGK01', 'Manuel', 'NEUER', 'Goalkeeper', 'GERMANY'); | T2: =LEN(A2) -> 7 | U2: =LEN(B2) -> 6 | V2: =LEN(C2) -> 5 | W2: =LEN(D2) -> 10 | X2: =LEN(E2) -> 7 | Y2: =LEN(#REF!) -> #REF! | Z2: =MIN(#REF!) -> #REF!
A3: GERGK02 | B3: Marc-André | C3: TER STEGEN | D3: Goalkeeper | E3: GERMANY | J3: Type Colonne | K3: Tab2_Goalkeeper | L3: String | M3: String | N3: String | O3: String | P3: String | S3: =CONCATENATE("INSERT INTO Tab2_Goalkeeper VALUES ('",A3,$S$1,B3,$S$1,C3,$S$1,D3,$S$1,E3,"');") -> INSERT INTO Tab2_Goalkeeper VALUES ('GERGK02', 'Marc-André', 'TER STEGEN', 'Goalkeeper', 'GERMANY'); | T3: =LEN(A3) -> 7 | U3: =LEN(B3) -> 10 | V3: =LEN(C3) -> 10 | W3: =LEN(D3) -> 10 | X3: =LEN(E3) -> 7 | Y3: =LEN(#REF!) -> #REF! | Z3: Max
A4: ENGGK03 | B4: Nick | C4: POPE | D4: Goalkeeper | E4: ENGLAND | J4: Longueur Colonne | K4: Tab2_Goalkeeper | L4: 7 | M4: 10 | N4: 10 | O4: 10 | P4: 11 | S4: =CONCATENATE("INSERT INTO Tab2_Goalkeeper VALUES ('",A4,$S$1,B4,$S$1,C4,$S$1,D4,$S$1,E4,"');") -> INSERT INTO Tab2_Goalkeeper VALUES ('ENGGK03', 'Nick', 'POPE', 'Goalkeeper', 'ENGLAND'); | T4: =LEN(A4) -> 7 | U4: =LEN(B4) -> 4 | V4: =LEN(C4) -> 4 | W4: =LEN(D4) -> 10 | X4: =LEN(E4) -> 7 | Y4: =LEN(#REF!) -> #REF! | Z4: =MAX(#REF!) -> #REF!
A5: ENGGK04 | B5: Jordan | C5: PICKFORD | D5: Goalkeeper | E5: ENGLAND | J5: Format Colonne | K5: Tab2_Goalkeeper | L5: CCCCCNN | M5: INITCAP | N5: UPPER | O5: INITCAP | P5: UPPER | S5: =CONCATENATE("INSERT INTO Tab2_Goalkeeper VALUES ('",A5,$S$1,B5,$S$1,C5,$S$1,D5,$S$1,E5,"');") -> INSERT INTO Tab2_Goalkeeper VALUES ('ENGGK04', 'Jordan', 'PICKFORD', 'Goalkeeper', 'ENGLAND'); | T5: =LEN(A5) -> 7 | U5: =LEN(B5) -> 6 | V5: =LEN(C5) -> 8 | W5: =LEN(D5) -> 10 | X5: =LEN(E5) -> 7 | Y5: =LEN(#REF!) -> #REF! | Z5: Moy
A6: ENGGK05 | B6: Aaron | C6: RAMSDALE | D6: Goalkeeper | E6: ENGLAND | J6: Langue Colonne | K6: Tab2_Goalkeeper | M6: Français/Anglais?? | N6: Français/Anglais?? | O6: Anglais | P6: Anglais | S6: =CONCATENATE("INSERT INTO Tab2_Goalkeeper VALUES ('",A6,$S$1,B6,$S$1,C6,$S$1,D6,$S$1,E6,"');") -> INSERT INTO Tab2_Goalkeeper VALUES ('ENGGK05', 'Aaron', 'RAMSDALE', 'Goalkeeper', 'ENGLAND'); | T6: =LEN(A6) -> 7 | U6: =LEN(B6) -> 5 | V6: =LEN(C6) -> 8 | W6: =LEN(D6) -> 10 | X6: =LEN(E6) -> 7 | Y6: =LEN(#REF!) -> #REF! | Z6: =AVERAGE(#REF!) -> #REF!
A7: ARGGK06 | B7: Emiliano | C7: MARTÍNEZ | D7: Goalkeeper | E7: ARGENTINA | J7: Valeurs Uniques | K7: Tab2_Goalkeeper | L7: Oui | M7: Non | N7: Non | O7: Non | P7: Non | S7: =CONCATENATE("INSERT INTO Tab2_Goalkeeper VALUES ('",A7,$S$1,B7,$S$1,C7,$S$1,D7,$S$1,E7,"');") -> INSERT INTO Tab2_Goalkeeper VALUES ('ARGGK06', 'Emiliano', 'MARTÍNEZ', 'Goalkeeper', 'ARGENTINA'); | T7: =LEN(A7) -> 7 | U7: =LEN(B7) -> 8 | V7: =LEN(C7) -> 8 | W7: =LEN(D7) -> 10 | X7: =LEN(E7) -> 9 | Y7: =LEN(#REF!) -> #REF!
A8: BELGK07 | B8: Thibaut | C8: COURTOIS | D8: Goalkeeper | E8: BELGIUM | J8: Nombre de Valeurs Présentes | K8: Tab2_Goalkeeper | L8: 20 | M8: 20 | N8: 20 | O8: 20 | P8: 20 | S8: =CONCATENATE("INSERT INTO Tab2_Goalkeeper VALUES ('",A8,$S$1,B8,$S$1,C8,$S$1,D8,$S$1,E8,"');") -> INSERT INTO Tab2_Goalkeeper VALUES ('BELGK07', 'Thibaut', 'COURTOIS', 'Goalkeeper', 'BELGIUM'); | T8: =LEN(A8) -> 7 | U8: =LEN(B8) -> 7 | V8: =LEN(C8) -> 8 | W8: =LEN(D8) -> 10 | X8: =LEN(E8) -> 7 | Y8: =LEN(#REF!) -> #REF! | Z8: Nbval | AA8: =COUNTA(A$2:A$157) -> 20 | AB8: =COUNTA(B$2:B$157) -> 20 | AC8: =COUNTA(C$2:C$157) -> 20 | AD8: =COUNTA(D$2:D$157) -> 20 | AE8: =COUNTA(E$2:E$157) -> 20
A9: BRAGK08 | B9: Becker | C9: ALISSON | D9: Goalkeeper | E9: BRAZIL | J9: Nombre de Valeurs Manquantes | K9: Tab2_Goalkeeper | L9: 0 | M9: 0 | N9: 0 | O9: 0 | P9: 0 | S9: =CONCATENATE("INSERT INTO Tab2_Goalkeeper VALUES ('",A9,$S$1,B9,$S$1,C9,$S$1,D9,$S$1,E9,"');") -> INSERT INTO Tab2_Goalkeeper VALUES ('BRAGK08', 'Becker', 'ALISSON', 'Goalkeeper', 'BRAZIL'); | T9: =LEN(A9) -> 7 | U9: =LEN(B9) -> 6 | V9: =LEN(C9) -> 7 | W9: =LEN(D9) -> 10 | X9: =LEN(E9) -> 6 | Y9: =LEN(#REF!) -> #REF!
A10: BRAGK09 | B10: Moraes | C10: EDERSON | D10: Goalkeeper | E10: BRAZIL | J10: Nombre de valeurs en UPPER uniquement | K10: Tab2_Goalkeeper | L10: 0 | M10: 0 | N10: 20 | O10: 0 | P10: 20 | S10: =CONCATENATE("INSERT INTO Tab2_Goalkeeper VALUES ('",A10,$S$1,B10,$S$1,C10,$S$1,D10,$S$1,E10,"');") -> INSERT INTO Tab2_Goalkeeper VALUES ('BRAGK09', 'Moraes', 'EDERSON', 'Goalkeeper', 'BRAZIL'); | T10: =LEN(A10) -> 7 | U10: =LEN(B10) -> 6 | V10: =LEN(C10) -> 7 | W10: =LEN(D10) -> 10 | X10: =LEN(E10) -> 6 | Y10: =LEN(#REF!) -> #REF!
A11: CAMGK10 | B11: André | C11: ONANA | D11: Goalkeeper | E11: CAMEROON | J11: Nombre de valeurs en LOWER uniquement | K11: Tab2_Goalkeeper | L11: 0 | M11: 0 | N11: 0 | O11: 0 | P11: 0 | S11: =CONCATENATE("INSERT INTO Tab2_Goalkeeper VALUES ('",A11,$S$1,B11,$S$1,C11,$S$1,D11,$S$1,E11,"');") -> INSERT INTO Tab2_Goalkeeper VALUES ('CAMGK10', 'André', 'ONANA', 'Goalkeeper', 'CAMEROON'); | T11: =LEN(A11) -> 7 | U11: =LEN(B11) -> 5 | V11: =LEN(C11) -> 5 | W11: =LEN(D11) -> 10 | X11: =LEN(E11) -> 8 | Y11: =LEN(#REF!) -> #REF!
A12: COSGK11 | B12: Keylor | C12: NAVAS | D12: Goalkeeper | E12: COSTA RICA | J12: Nombre de valeurs en INITCAP uniquement | K12: Tab2_Goalkeeper | L12: 20 | M12: 20 | N12: 20 | O12: 20 | P12: 0 | S12: =CONCATENATE("INSERT INTO Tab2_Goalkeeper VALUES ('",A12,$S$1,B12,$S$1,C12,$S$1,D12,$S$1,E12,"');") -> INSERT INTO Tab2_Goalkeeper VALUES ('COSGK11', 'Keylor', 'NAVAS', 'Goalkeeper', 'COSTA RICA'); | T12: =LEN(A12) -> 7 | U12: =LEN(B12) -> 6 | V12: =LEN(C12) -> 5 | W12: =LEN(D12) -> 10 | X12: =LEN(E12) -> 10 | Y12: =LEN(#REF!) -> #REF!
A13: CROGK12 | B13: Dominik | C13: LIVAKOVIĆ | D13: Goalkeeper | E13: CROATIA | J13: Nombre de valeurs en MIXTE | K13: Tab2_Goalkeeper | L13: 0 | M13: 0 | N13: 0 | O13: 0 | P13: 0 | S13: =CONCATENATE("INSERT INTO Tab2_Goalkeeper VALUES ('",A13,$S$1,B13,$S$1,C13,$S$1,D13,$S$1,E13,"');") -> INSERT INTO Tab2_Goalkeeper VALUES ('CROGK12', 'Dominik', 'LIVAKOVIĆ', 'Goalkeeper', 'CROATIA'); | T13: =LEN(A13) -> 7 | U13: =LEN(B13) -> 7 | V13: =LEN(C13) -> 9 | W13: =LEN(D13) -> 10 | X13: =LEN(E13) -> 7 | Y13: =LEN(#REF!) -> #REF!
A14: FRAGK13 | B14: Hugo | C14: LLORIS | D14: Goalkeeper | E14: FRANCE | J14: REGEX Colonne | K14: Tab2_Goalkeeper | L14: ^[A..Za..z] ?-.öè | M14: ^[A..Za..z] ?-.öè | N14: ^[A..Za..z] ?-.öè | O14: ^[A..Za..z] ?-.öè | P14: ^[A..Za..z] ?-.öè | S14: =CONCATENATE("INSERT INTO Tab2_Goalkeeper VALUES ('",A14,$S$1,B14,$S$1,C14,$S$1,D14,$S$1,E14,"');") -> INSERT INTO Tab2_Goalkeeper VALUES ('FRAGK13', 'Hugo', 'LLORIS', 'Goalkeeper', 'FRANCE'); | T14: =LEN(A14) -> 7 | U14: =LEN(B14) -> 4 | V14: =LEN(C14) -> 6 | W14: =LEN(D14) -> 10 | X14: =LEN(E14) -> 6 | Y14: =LEN(#REF!) -> #REF!
A15: FRAGK14 | B15: Mike | C15: MAIGNAN | D15: Goalkeeper | E15: FRANCE | J15: Nombre de valeurs avec ESPACE | K15: Tab2_Goalkeeper | S15: =CONCATENATE("INSERT INTO Tab2_Goalkeeper VALUES ('",A15,$S$1,B15,$S$1,C15,$S$1,D15,$S$1,E15,"');") -> INSERT INTO Tab2_Goalkeeper VALUES ('FRAGK14', 'Mike', 'MAIGNAN', 'Goalkeeper', 'FRANCE'); | T15: =LEN(A15) -> 7 | U15: =LEN(B15) -> 4 | V15: =LEN(C15) -> 7 | W15: =LEN(D15) -> 10 | X15: =LEN(E15) -> 6 | Y15: =LEN(#REF!) -> #REF!
A16: ITAGK15 | B16: Gianluigi | C16: DONNARUMMA | D16: Goalkeeper | E16: ITALY | J16: Nombre de valeurs avec TIRET | K16: Tab2_Goalkeeper | S16: =CONCATENATE("INSERT INTO Tab2_Goalkeeper VALUES ('",A16,$S$1,B16,$S$1,C16,$S$1,D16,$S$1,E16,"');") -> INSERT INTO Tab2_Goalkeeper VALUES ('ITAGK15', 'Gianluigi', 'DONNARUMMA', 'Goalkeeper', 'ITALY'); | T16: =LEN(A16) -> 7 | U16: =LEN(B16) -> 9 | V16: =LEN(C16) -> 10 | W16: =LEN(D16) -> 10 | X16: =LEN(E16) -> 5 | Y16: =LEN(#REF!) -> #REF!
A17: MEXGK16 | B17: Guillermo | C17: OCHOA | D17: Goalkeeper | E17: MEXICO | J17: Nombre de valeurs avec APOSTROPHE | K17: Tab2_Goalkeeper | S17: =CONCATENATE("INSERT INTO Tab2_Goalkeeper VALUES ('",A17,$S$1,B17,$S$1,C17,$S$1,D17,$S$1,E17,"');") -> INSERT INTO Tab2_Goalkeeper VALUES ('MEXGK16', 'Guillermo', 'OCHOA', 'Goalkeeper', 'MEXICO'); | T17: =LEN(A17) -> 7 | U17: =LEN(B17) -> 9 | V17: =LEN(C17) -> 5 | W17: =LEN(D17) -> 10 | X17: =LEN(E17) -> 6 | Y17: =LEN(#REF!) -> #REF!
A18: POLGK17 | B18: Wojciech | C18: SZCZĘSNY | D18: Goalkeeper | E18: POLAND | J18: Nombre de valeurs INCORRECTES | K18: Tab2_Goalkeeper | S18: =CONCATENATE("INSERT INTO Tab2_Goalkeeper VALUES ('",A18,$S$1,B18,$S$1,C18,$S$1,D18,$S$1,E18,"');") -> INSERT INTO Tab2_Goalkeeper VALUES ('POLGK17', 'Wojciech', 'SZCZĘSNY', 'Goalkeeper', 'POLAND'); | T18: =LEN(A18) -> 7 | U18: =LEN(B18) -> 8 | V18: =LEN(C18) -> 8 | W18: =LEN(D18) -> 10 | X18: =LEN(E18) -> 6 | Y18: =LEN(#REF!) -> #REF!
A19: SLOGK18 | B19: Jan | C19: OBLAK | D19: Goalkeeper | E19: SLOVENIA | J19: Nombre de valeurs CORRECTES | K19: Tab2_Goalkeeper | S19: =CONCATENATE("INSERT INTO Tab2_Goalkeeper VALUES ('",A19,$S$1,B19,$S$1,C19,$S$1,D19,$S$1,E19,"');") -> INSERT INTO Tab2_Goalkeeper VALUES ('SLOGK18', 'Jan', 'OBLAK', 'Goalkeeper', 'SLOVENIA'); | T19: =LEN(A19) -> 7 | U19: =LEN(B19) -> 3 | V19: =LEN(C19) -> 5 | W19: =LEN(D19) -> 10 | X19: =LEN(E19) -> 8 | Y19: =LEN(#REF!) -> #REF!
A20: SWIGK19 | B20: Yann | C20: SOMMER | D20: Goalkeeper | E20: SWITZERLAND | J20: Nombre de doublons exacts | K20: Tab2_Goalkeeper | S20: =CONCATENATE("INSERT INTO Tab2_Goalkeeper VALUES ('",A20,$S$1,B20,$S$1,C20,$S$1,D20,$S$1,E20,"');") -> INSERT INTO Tab2_Goalkeeper VALUES ('SWIGK19', 'Yann', 'SOMMER', 'Goalkeeper', 'SWITZERLAND'); | T20: =LEN(A20) -> 7 | U20: =LEN(B20) -> 4 | V20: =LEN(C20) -> 6 | W20: =LEN(D20) -> 10 | X20: =LEN(E20) -> 11 | Y20: =LEN(#REF!) -> #REF!
A21: UKRGK20 | B21: Anatoliy | C21: TRUBIN | D21: Goalkeeper | E21: UKRAINE | J21: Min Colonne | K21: Tab2_Goalkeeper | S21: =CONCATENATE("INSERT INTO Tab2_Goalkeeper VALUES ('",A21,$S$1,B21,$S$1,C21,$S$1,D21,$S$1,E21,"');") -> INSERT INTO Tab2_Goalkeeper VALUES ('UKRGK20', 'Anatoliy', 'TRUBIN', 'Goalkeeper', 'UKRAINE'); | T21: =LEN(A21) -> 7 | U21: =LEN(B21) -> 8 | V21: =LEN(C21) -> 6 | W21: =LEN(D21) -> 10 | X21: =LEN(E21) -> 7 | Y21: =LEN(#REF!) -> #REF!
J22: Max Colonne | K22: Tab2_Goalkeeper | T22: =LEN(A22) -> 0 | U22: =LEN(B22) -> 0 | V22: =LEN(C22) -> 0 | W22: =LEN(D22) -> 0 | X22: =LEN(E22) -> 0 | Y22: =LEN(#REF!) -> #REF!
